<?xml version="1.0" encoding="UTF-8"?>
<testng-results skipped="0" failed="1" total="4" passed="3">
  <reporter-output>
  </reporter-output>
  <suite name="Default suite" duration-ms="44" started-at="2017-01-15T19:28:15Z" finished-at="2017-01-15T19:28:15Z">
    <groups>
    </groups>
    <test name="Default test" duration-ms="44" started-at="2017-01-15T19:28:15Z" finished-at="2017-01-15T19:28:15Z">
      <class name="test.testcalc">
        <test-method status="PASS" signature="testAdd()[pri:0, instance:test.testcalc@458ad742]" name="testAdd" duration-ms="12" started-at="2017-01-15T23:28:15Z" finished-at="2017-01-15T23:28:15Z">
          <reporter-output>
          </reporter-output>
        </test-method> <!-- testAdd -->
        <test-method status="PASS" signature="testDivide()[pri:0, instance:test.testcalc@458ad742]" name="testDivide" duration-ms="2" started-at="2017-01-15T23:28:15Z" finished-at="2017-01-15T23:28:15Z">
          <reporter-output>
          </reporter-output>
        </test-method> <!-- testDivide -->
        <test-method status="PASS" signature="testMultiply()[pri:0, instance:test.testcalc@458ad742]" name="testMultiply" duration-ms="2" started-at="2017-01-15T23:28:15Z" finished-at="2017-01-15T23:28:15Z">
          <reporter-output>
          </reporter-output>
        </test-method> <!-- testMultiply -->
        <test-method status="FAIL" signature="testSubStract()[pri:0, instance:test.testcalc@458ad742]" name="testSubStract" duration-ms="4" started-at="2017-01-15T23:28:15Z" finished-at="2017-01-15T23:28:15Z">
          <exception class="java.lang.AssertionError">
            <message>
              <![CDATA[expected [2] but found [1]]]>
            </message>
            <full-stacktrace>
              <![CDATA[java.lang.AssertionError: expected [2] but found [1]
	at org.testng.Assert.fail(Assert.java:94)
	at org.testng.Assert.failNotEquals(Assert.java:513)
	at org.testng.Assert.assertEqualsImpl(Assert.java:135)
	at org.testng.Assert.assertEquals(Assert.java:116)
	at org.testng.Assert.assertEquals(Assert.java:389)
	at org.testng.Assert.assertEquals(Assert.java:399)
	at test.testcalc.testSubStract(testcalc.java:38)
	at sun.reflect.NativeMethodAccessorImpl.invoke0(Native Method)
	at sun.reflect.NativeMethodAccessorImpl.invoke(Unknown Source)
	at sun.reflect.DelegatingMethodAccessorImpl.invoke(Unknown Source)
	at java.lang.reflect.Method.invoke(Unknown Source)
	at org.testng.internal.MethodInvocationHelper.invokeMethod(MethodInvocationHelper.java:100)
	at org.testng.internal.Invoker.invokeMethod(Invoker.java:646)
	at org.testng.internal.Invoker.invokeTestMethod(Invoker.java:811)
	at org.testng.internal.Invoker.invokeTestMethods(Invoker.java:1129)
	at org.testng.internal.TestMethodWorker.invokeTestMethods(TestMethodWorker.java:129)
	at org.testng.internal.TestMethodWorker.run(TestMethodWorker.java:112)
	at org.testng.TestRunner.privateRun(TestRunner.java:746)
	at org.testng.TestRunner.run(TestRunner.java:600)
	at org.testng.SuiteRunner.runTest(SuiteRunner.java:366)
	at org.testng.SuiteRunner.runSequentially(SuiteRunner.java:361)
	at org.testng.SuiteRunner.privateRun(SuiteRunner.java:319)
	at org.testng.SuiteRunner.run(SuiteRunner.java:268)
	at org.testng.SuiteRunnerWorker.runSuite(SuiteRunnerWorker.java:52)
	at org.testng.SuiteRunnerWorker.run(SuiteRunnerWorker.java:86)
	at org.testng.TestNG.runSuitesSequentially(TestNG.java:1264)
	at org.testng.TestNG.runSuitesLocally(TestNG.java:1189)
	at org.testng.TestNG.runSuites(TestNG.java:1104)
	at org.testng.TestNG.run(TestNG.java:1076)
	at org.testng.remote.AbstractRemoteTestNG.run(AbstractRemoteTestNG.java:126)
	at org.testng.remote.RemoteTestNG.initAndRun(RemoteTestNG.java:152)
	at org.testng.remote.RemoteTestNG.main(RemoteTestNG.java:57)
]]>
            </full-stacktrace>
          </exception> <!-- java.lang.AssertionError -->
          <reporter-output>
          </reporter-output>
        </test-method> <!-- testSubStract -->
      </class> <!-- test.testcalc -->
    </test> <!-- Default test -->
  </suite> <!-- Default suite -->
</testng-results>
